Workbook

Sheet ScaInit

Sheet PLT_201_MST_032_V1
J1: CENTRALES ELÉCTRICAS DEL NORTE DE SANTANDER S.A. E.S.P. SISTEMA DE GESTIÓN INTEGRADO
J3: PLANILLA DE REGISTRO SUBESTACIÓN LA MIEL
A4: NÚMERO OT | AB4: FECHA (dd/mm/aa) | BJ4: Pág 1 de 2
A5: EJECUTÓ | BE5: HORA
A6: CONVENCIONES | L6: X | N6: PARA REVISAR | W6: P | Y6: PENDIENTE | AG6: U | AI6: URGENTE | AR6: √ | AT6: BUEN ESTADO Y/O NORMAL | BJ6: NA | BL6: NO APLICA
A7: NIVEL 34.5KV
A8: TRANSFORMADORES DE TENSIÓN Y DPS 34.5 KV
A10: DETALLE | J10: TRANSFORMADORES DE TENSIÓN | AB10: DPS | AE10: CONT. DESC. DPS FP | AN10: FASE R | AY10: FASE R | BJ10: FASE S
J11: FASE A | P11: FASE B | V11: FASE C | AB11: FP
A12: Conectores | AE12: OBSERVACIONES:
A13: Porcelana
A14: Caja de agrupamiento
A15: Limpieza
A16: Cableado
A17: Puesta a tierra
A18: SECCIONADORES ASOCIADOS 34.5 KV
A20: Seccionadores | J20: SB11 | N20: ST12 | R20: Seccionadores | AA20: SB11 | AE20: ST12 | AI20: OBSERVACIONES:
A21: Estado | R21: Estado
A22: Conectores | R22: Gab. De Control
A23: Porcelana | R23: Aisladores
A24: Mecanismo | R24: Puesta a tierra
A25: Accionamiento
A26: TRANSFORMADOR DE CORRIENTE | M26: INTERRUPTOR DE 34.5KV IT 10 | BF26: PRESIONES DE SF6 Y MANIOBRAS INTERRUPTOR IT10
M27: DETALLE | X27: IT10 | AB27: DETALLE | AM27: IT10 | AQ27: DETALLE | BB27: IT10
A28: Conectores | M28: Conectores | AB28: Mangueras presión | AQ28: Breakers | BF28: Presión Nominal
A29: Porcelana | M29: Conductores eléctr. | AB29: Estructura metálica | AQ29: Iluminación
A30: Caja de agrupamiento | M30: Porcelana | AB30: Puesta a tierra | AQ30: DPS | BF30: Presión Leída
A31: Limpieza | M31: Sistema mecánico | AB31: Gabinete de control | AQ31: Mandos
A32: Cableado | M32: Presión de SF6 | AB32: Borneras | AQ32: Calefacción | BF32: Número Maniobras interruptor IT10
A33: Puesta a tierra | M33: Manómetros | AB33: Cableado | AQ33: Limpieza
A34: OBSERVACIONES:
A35: TRANSFORMADOR 34.5/13.8kV | AM35: Contador de descargas | BB35: Estado silica gel | BM35: Nivel de aceite
A36: Conductores primarios | T36: Gabinete de control | AM36: FASES | AR36: PRIM. | AW36: SECUND.
A37: Conectores | T37: Breaker | AM37: FASE R | BR37: OLTC
A38: Bujes primarios | T38: Bornera | AM38: FASE S | BB38: Color actual del GEL | BM38: 80ºC Max.
A39: Bujes secundarios | T39: Cableado | AM39: FASE T | BB39: Posición conmutador
A40: Silica gel | T40: Iluminación | AM40: TEMPERATURAS | BM40: 25ºC Norm
A41: Termómetro del aceite | T41: Limpieza | AM41: Aceite | AR41: AT | AW41: BT
A42: Termómetro devanado | T42: Mandos | BM42: 20ºC Min
A43: Conduct. secundarios | T43: DPS
...

Sheet PLT_201_MST_032_ACT
J1: CENTRALES ELÉCTRICAS DEL NORTE DE SANTANDER S.A. E.S.P. SISTEMA DE GESTIÓN INTEGRADO
J3: PLANILLA DE REGISTRO SUBESTACIÓN LA MIEL- MAPEO POR CELDAS
A4: NÚMERO OT | J4: J4 | AB4: FECHA (dd/mm/aa) | AN4: AN4 | BJ4: Pág 1 de 2
A5: EJECUTÓ | J5: J5 | BE5: HORA | BJ5: BJ15
A6: CONVENCIONES | L6: X | N6: PARA REVISAR | W6: P | Y6: PENDIENTE | AG6: U | AI6: URGENTE | AR6: √ | AT6: BUEN ESTADO Y/O NORMAL | BJ6: NA | BL6: NO APLICA
A7: NIVEL 34.5KV
A8: 2. TRANSFORMADORES DE TENSIÓN Y DPS 34.5 KV
A10: DETALLE | J10: TRANSFORMADORES DE TENSIÓN | AB10: DPS | AE10: CONT. DESC. DPS FP | AN10: FASE R | AS10: AS10 | AY10: FASE R | BD10: BD10 | BJ10: FASE S | BO10: BQ10
J11: FASE A | P11: FASE B | V11: FASE C | AB11: FP
A12: Conectores | J12: J12 | P12: P12 | V12: V12 | AB12: AB12 | AE12: OBSERVACIONES:
A13: Porcelana | J13: J13 | P13: P13 | V13: V13 | AB13: AB13 | AE13: AE10
A14: Caja de agrupamiento | J14: J14 | P14: P14 | V14: V14 | AB14: AB14
A15: Limpieza | J15: J15 | P15: P15 | V15: V15 | AB15: AB15
A16: Cableado | J16: J16 | P16: P16 | V16: V16 | AB16: AB16
A17: Puesta a tierra | J17: J17 | P17: P17 | V17: V17 | AB17: AB17
A18: 3. SECCIONADORES ASOCIADOS 34.5 KV
A20: Seccionadores | J20: SB11 | N20: ST12 | R20: Seccionadores | AA20: SB11 | AE20: ST12 | AI20: OBSERVACIONES:
A21: Estado | J21: J21 | N21: N21 | R21: Estado | AA21: AA21 | AE21: AE21 | AI21: AI21
A22: Conectores | J22: J22 | N22: N22 | R22: Gab. De Control | AA22: AA22 | AE22: AE22
A23: Porcelana | J23: J23 | N23: N23 | R23: Aisladores | AA23: AA23 | AE23: AE23
A24: Mecanismo | J24: J24 | N24: N24 | R24: Puesta a tierra | AA24: AA24 | AE24: AE24
A25: Accionamiento | J25: J25 | N25: N25
A26: 4, TRANSFORMADOR DE CORRIENTE 34.5 KV | M26: 4, INTERRUPTOR DE 34.5KV IT 10 | BF26: 4, PRESIONES DE SF6 Y MANIOBRAS INTERRUPTOR IT10
M27: DETALLE | X27: IT10 | AB27: DETALLE | AM27: IT10 | AQ27: DETALLE | BB27: IT10
A28: Conectores | H28: H28 | M28: Conectores | X28: X28 | AB28: Mangueras presión | AM28: AM28 | AQ28: Breakers | BB28: BB28 | BF28: Presión Nominal | BP28: BP28
A29: Porcelana | H29: H29 | M29: Conductores eléctr. | X29: X29 | AB29: Estructura metálica | AM29: AM29 | AQ29: Iluminación | BB29: BB29
A30: Caja de agrupamiento | H30: H30 | M30: Porcelana | X30: X30 | AB30: Puesta a tierra | AM30: AM30 | AQ30: DPS | BB30: BB30 | BF30: Presión Leída | BP30: BP30
A31: Limpieza | H31: H31 | M31: Sistema mecánico | X31: X31 | AB31: Gabinete de control | AM31: AM31 | AQ31: Mandos | BB31: BB31
A32: Cableado | H32: H32 | M32: Presión de SF6 | X32: X32 | AB32: Borneras | AM32: AM32 | AQ32: Calefacción | BB32: BB32 | BF32: Número Maniobras interruptor IT10 | BP32: BP32
A33: Puesta a tierra | H33: H33 | M33: Manómetros | X33: X33 | AB33: Cableado | AM33: AM33 | AQ33: Limpieza | BB33: BB33
A34: OBSERVACIONES: | AM34: am34
A35: 5, TRANSFORMADOR 34.5/13.8kV | AM35: 5, Contador de descargas | BB35: 5, Estado silica gel | BM35: 5, Nivel de aceite
A36: Conductores primarios | M36: M36 | T36: Gabinete de control | AF36: AF36 | AM36: FASES | AR36: PRIM. | AW36: SECUND.
A37: Conectores | M37: M37 | T37: Breaker | AF37: AF37 | AM37: FASE R | AR37: AR37 | AW37: AW37 | BB37: BB37 | BR37: OLTC
A38: Bujes primarios | M38: M38 | T38: Bornera | AF38: AF38 | AM38: FASE S | AR38: AR38 | AW38: aw38 | BB38: Color actual del GEL | BG38: BG38 | BM38: 80ºC Max. | BS38: BS38
A39: Bujes secundarios | M39: M39 | T39: Cableado | AF39: AF39 | AM39: FASE T | AR39: AR39 | AW39: AW39 | BB39: Posición conmutador
A40: Silica gel | M40: M40 | T40: Iluminación | AF40: AF40 | AM40: TEMPERATURAS | BM40: 25ºC Norm | BS40: BS40
A41: Termómetro del aceite | M41: M41 | T41: Limpieza | AF41: AF41 | AM41: Aceite | AR41: AT | AW41: BT
A42: Termómetro devanado | M42: M42 | T42: Mandos | AF42: AF42 | AM42: AM42 | AR42: AR42 | AW42: AW42 | BB42: BB42 | BM42: 20ºC Min | BS42: BS42
A43: Conduct. secundarios | M43: M43 | T43: DPS | AF43: AF43
...

Sheet Hoja1
A1: Num | B1: Nombre | C1: ID | D1: Tipo de Entrada | E1: Mapeo | F1: Pagina | G1: Fila
A2: 1 | B2: fecha | C2: fecha | D2: date | E2: =+PLT_201_MST_032_ACT!AN4 -> AN4 | F2: 1. Datos Generales | G2: 100
A3: 2 | B3: ejecuto | C3: ejecuto | D3: text | E3: =+PLT_201_MST_032_ACT!J4 -> J4 | F3: 1. Datos Generales | G3: 105
A4: 3 | B4: UMERO OT | C4: umero_ot | D4: text | E4: =+PLT_201_MST_032_ACT!J5 -> J5 | F4: 1. Datos Generales | G4: 110
A5: 4 | B5: id_tt_fase_r | C5: id_tt_fase_r | D5: textarea | E5: =+PLT_201_MST_032_ACT!AS10 -> AS10 | F5: 2. NIVEL 13.8kV — TRANSFORMADORES DE TENSIÓN Y DPS 34.5 KV | G5: 145
A6: 5 | B6: id_tt_fase_s | C6: id_tt_fase_s | D6: textarea | E6: =+PLT_201_MST_032_ACT!BD10 -> BD10 | F6: 2. NIVEL 13.8kV — TRANSFORMADORES DE TENSIÓN Y DPS 34.5 KV | G6: 147
A7: 6 | B7: id__tt_fase_t | C7: id__tt_fase_t | D7: textarea | E7: =+PLT_201_MST_032_ACT!BO10 -> BQ10 | F7: 2. NIVEL 13.8kV — TRANSFORMADORES DE TENSIÓN Y DPS 34.5 KV | G7: 149
A8: 7 | B8: id_tt2p2f2_conectores_fase_a | C8: id_tt2p2f2_conectores_fase_a | D8: select | E8: =+PLT_201_MST_032_ACT!J12 -> J12 | F8: 2. NIVEL 13.8kV — TRANSFORMADORES DE TENSIÓN Y DPS 34.5 KV | G8: 153
A9: 8 | B9: id_ttp2f3_conectores_fase_b | C9: id_ttp2f3_conectores_fase_b | D9: select | E9: =+PLT_201_MST_032_ACT!P12 -> P12 | F9: 2. NIVEL 13.8kV — TRANSFORMADORES DE TENSIÓN Y DPS 34.5 KV | G9: 154
A10: 9 | B10: id_ttp2f3_conectores_fase_c | C10: id_ttp2f3_conectores_fase_c | D10: select | E10: =+PLT_201_MST_032_ACT!V12 -> V12 | F10: 2. NIVEL 13.8kV — TRANSFORMADORES DE TENSIÓN Y DPS 34.5 KV | G10: 155
A11: 10 | B11: id_ttp2f3_conectores_ft | C11: id_ttp2f3_conectores_ft | D11: select | E11: =+PLT_201_MST_032_ACT!AB12 -> AB12 | F11: 2. NIVEL 13.8kV — TRANSFORMADORES DE TENSIÓN Y DPS 34.5 KV | G11: 156
A12: 11 | B12: observaciones | C12: observaciones | D12: text | E12: ae13 | F12: 2. NIVEL 13.8kV — TRANSFORMADORES DE TENSIÓN Y DPS 34.5 KV | G12: 158
A13: 12 | B13: id_ttp2f3_porcelana_fase_a | C13: id_ttp2f3_porcelana_fase_a | D13: select | E13: =+PLT_201_MST_032_ACT!J13 -> J13 | F13: 2. NIVEL 13.8kV — TRANSFORMADORES DE TENSIÓN Y DPS 34.5 KV | G13: 162
A14: 13 | B14: id_ttp2f3_porcelana_fase_b | C14: id_ttp2f3_porcelana_fase_b | D14: select | E14: =+PLT_201_MST_032_ACT!P13 -> P13 | F14: 2. NIVEL 13.8kV — TRANSFORMADORES DE TENSIÓN Y DPS 34.5 KV | G14: 163
A15: 14 | B15: id_ttp2f3_porcelana_fase_c | C15: id_ttp2f3_porcelana_fase_c | D15: select | E15: =+PLT_201_MST_032_ACT!V13 -> V13 | F15: 2. NIVEL 13.8kV — TRANSFORMADORES DE TENSIÓN Y DPS 34.5 KV | G15: 164
A16: 15 | B16: id_ttp2f3__porcelana_fase_ft | C16: id_ttp2f3__porcelana_fase_ft | D16: select | E16: =+PLT_201_MST_032_ACT!AB13 -> AB13 | F16: 2. NIVEL 13.8kV — TRANSFORMADORES DE TENSIÓN Y DPS 34.5 KV | G16: 165
A17: 16 | B17: id_ttp2f4_Caja_agrupamiento_fase_a | C17: id_ttp2f4_caja_agrupamiento_fase_a | D17: select | E17: =+PLT_201_MST_032_ACT!J14 -> J14 | F17: 2. NIVEL 13.8kV — TRANSFORMADORES DE TENSIÓN Y DPS 34.5 KV | G17: 169
A18: 17 | B18: id_ttp2f4_Caja_agrupamiento_fase_b | C18: id_ttp2f4_caja_agrupamiento_fase_b | D18: select | E18: =+PLT_201_MST_032_ACT!P14 -> P14 | F18: 2. NIVEL 13.8kV — TRANSFORMADORES DE TENSIÓN Y DPS 34.5 KV | G18: 170
A19: 18 | B19: id_ttp2f4Caja_agrupamiento_fase_c | C19: id_ttp2f4caja_agrupamiento_fase_c | D19: select | E19: =+PLT_201_MST_032_ACT!V14 -> V14 | F19: 2. NIVEL 13.8kV — TRANSFORMADORES DE TENSIÓN Y DPS 34.5 KV | G19: 171
A20: 19 | B20: id_ttp2f4_Caja_agrupamiento_fase_ft | C20: id_ttp2f4_caja_agrupamiento_fase_ft | D20: select | E20: =+PLT_201_MST_032_ACT!AB14 -> AB14 | F20: 2. NIVEL 13.8kV — TRANSFORMADORES DE TENSIÓN Y DPS 34.5 KV | G20: 172
A21: 20 | B21: id_ttp2f5_Limpieza_fase_a | C21: id_ttp2f5_limpieza_fase_a | D21: select | E21: =+PLT_201_MST_032_ACT!J15 -> J15 | F21: 2. NIVEL 13.8kV — TRANSFORMADORES DE TENSIÓN Y DPS 34.5 KV | G21: 176
A22: 21 | B22: id_ttp2f5_Limpieza_fase_b | C22: id_ttp2f5_limpieza_fase_b | D22: select | E22: =+PLT_201_MST_032_ACT!P15 -> P15 | F22: 2. NIVEL 13.8kV — TRANSFORMADORES DE TENSIÓN Y DPS 34.5 KV | G22: 177
A23: 22 | B23: id_ttp2f5_Limpieza_fase_c | C23: id_ttp2f5_limpieza_fase_c | D23: select | E23: =+PLT_201_MST_032_ACT!V15 -> V15 | F23: 2. NIVEL 13.8kV — TRANSFORMADORES DE TENSIÓN Y DPS 34.5 KV | G23: 178
A24: 23 | B24: id_ttp2f5_Limpieza_ft | C24: id_ttp2f5_limpieza_ft | D24: select | E24: =+PLT_201_MST_032_ACT!AB15 -> AB15 | F24: 2. NIVEL 13.8kV — TRANSFORMADORES DE TENSIÓN Y DPS 34.5 KV | G24: 179
A25: 24 | B25: id_ttp2f6_Limpiez-Cableado_fase_a | C25: id_ttp2f6_limpiez_cableado_fase_a | D25: select | E25: =+PLT_201_MST_032_ACT!J16 -> J16 | F25: 2. NIVEL 13.8kV — TRANSFORMADORES DE TENSIÓN Y DPS 34.5 KV | G25: 183
A26: 25 | B26: id_ttp2f6_Limpiez-Cableado_fase_b | C26: id_ttp2f6_limpiez_cableado_fase_b | D26: select | E26: =+PLT_201_MST_032_ACT!P16 -> P16 | F26: 2. NIVEL 13.8kV — TRANSFORMADORES DE TENSIÓN Y DPS 34.5 KV | G26: 184
A27: 26 | B27: id_ttp2f6_Limpiez-Cableado_fase_c | C27: id_ttp2f6_limpiez_cableado_fase_c | D27: select | E27: =+PLT_201_MST_032_ACT!V16 -> V16 | F27: 2. NIVEL 13.8kV — TRANSFORMADORES DE TENSIÓN Y DPS 34.5 KV | G27: 185
A28: 27 | B28: id_ttp2f6_Limpiez-Cableado_fase_ft | C28: id_ttp2f6_limpiez_cableado_fase_ft | D28: select | E28: =+PLT_201_MST_032_ACT!AB16 -> AB16 | F28: 2. NIVEL 13.8kV — TRANSFORMADORES DE TENSIÓN Y DPS 34.5 KV | G28: 186
A29: 28 | B29: id_ttp2f7_Limpieza_Puesta_tierra_fase_a | C29: id_ttp2f7_limpieza_puesta_tierra_fase_a | D29: select | E29: =+PLT_201_MST_032_ACT!J17 -> J17 | F29: 2. NIVEL 13.8kV — TRANSFORMADORES DE TENSIÓN Y DPS 34.5 KV | G29: 190
A30: 29 | B30: id_ttp2f7_Limpieza_Puesta_tierra_fase_b | C30: id_ttp2f7_limpieza_puesta_tierra_fase_b | D30: select | E30: =+PLT_201_MST_032_ACT!P17 -> P17 | F30: 2. NIVEL 13.8kV — TRANSFORMADORES DE TENSIÓN Y DPS 34.5 KV | G30: 191
A31: 30 | B31: id_ttp2f7_Limpieza_Puesta_tierra_fase_c | C31: id_ttp2f7_limpieza_puesta_tierra_fase_c | D31: select | E31: =+PLT_201_MST_032_ACT!V17 -> V17 | F31: 2. NIVEL 13.8kV — TRANSFORMADORES DE TENSIÓN Y DPS 34.5 KV | G31: 192
A32: 31 | B32: id_ttp2f7_Limpieza_Puesta_tierra_ft | C32: id_ttp2f7_limpieza_puesta_tierra_ft | D32: select | E32: =+PLT_201_MST_032_ACT!AB17 -> AB17 | F32: 2. NIVEL 13.8kV — TRANSFORMADORES DE TENSIÓN Y DPS 34.5 KV | G32: 193
A33: 32 | B33: OBSERVACIONES | C33: observaciones_1 | D33: text | E33: =+PLT_201_MST_032_ACT!AE13 -> AE10 | F33: 3. NIVEL 13.8kV — SECCIONADORES ASOCIADOS 34.5 KV | G33: 211
A34: 33 | B34: it_Estado | C34: it_estado_sb11 | D34: select | E34: =+PLT_201_MST_032_ACT!J21 -> J21 | F34: 3. NIVEL 13.8kV — SECCIONADORES ASOCIADOS 34.5 KV | G34: 215
A35: 34 | B35: it_Estado | C35: it_estado_1_sb12 | D35: select | E35: =+PLT_201_MST_032_ACT!N21 -> N21 | F35: 3. NIVEL 13.8kV — SECCIONADORES ASOCIADOS 34.5 KV | G35: 216
A36: 35 | B36: it_Conectores_SB11 | C36: it_conectores_sb11 | D36: select | E36: =+PLT_201_MST_032_ACT!J22 -> J22 | F36: 3. NIVEL 13.8kV — SECCIONADORES ASOCIADOS 34.5 KV | G36: 221
A37: 36 | B37: it_Conectores_SB12 | C37: it_conectores_sb12 | D37: select | E37: =+PLT_201_MST_032_ACT!N22 -> N22 | F37: 3. NIVEL 13.8kV — SECCIONADORES ASOCIADOS 34.5 KV | G37: 222
A38: 37 | B38: it_Porcelana_SB11 | C38: it_porcelana_sb11 | D38: select | E38: =+PLT_201_MST_032_ACT!J23 -> J23 | F38: 3. NIVEL 13.8kV — SECCIONADORES ASOCIADOS 34.5 KV | G38: 226
A39: 38 | B39: it_Porcelana_SB12 | C39: it_porcelana_sb12 | D39: select | E39: =+PLT_201_MST_032_ACT!N23 -> N23 | F39: 3. NIVEL 13.8kV — SECCIONADORES ASOCIADOS 34.5 KV | G39: 227
A40: 39 | B40: it_Mecanismo | C40: it_mecanismo | D40: select | E40: =+PLT_201_MST_032_ACT!J24 -> J24 | F40: 3. NIVEL 13.8kV — SECCIONADORES ASOCIADOS 34.5 KV | G40: 231
...
